<robot name="robot_7">
  
  <link name="world"/>
<link name="link1">
    <collision>
        <origin xyz="0 0 0.5" rpy="0 0 0"/>
        <geometry> <box size="0.1 0.1 1" /> </geometry>
        <contact_coefficients kd="1.0" kp="1000.0" mu="0"/>
    </collision>
    <visual>
        <origin xyz="0 0 0.5" rpy="0 0 0"/>
        <geometry> <box size="0.1 0.1 1" /> </geometry>
        <material name="white"> <color rgba="1.0 1.0 1.0 1.0"/> </material>
    </visual>
    <inertial>
        <origin xyz="0 0 0.5" rpy="0 0 0"/>
        <mass value="0.030"/>
        <inertia ixx="0.001" ixy="0.0"  ixz="0.0"  iyy="0.001"  iyz="0.0"  izz="0.001"/>
    </inertial>
</link>

<link name="link2">
    <collision>
        <origin xyz="0 0 0.5" rpy="0 0 0"/>
        <geometry> <box size="0.1 0.1 1" /> </geometry>
        <contact_coefficients kd="1.0" kp="1000.0" mu="0"/>
    </collision>
    <visual>
        <origin xyz="0 0 0.5" rpy="0 0 0"/>
        <geometry> <box size="0.1 0.1 1" /> </geometry>
        <material name="white"> <color rgba="1.0 1.0 1.0 1.0"/> </material>
    </visual>
    <inertial>
        <origin xyz="0 0 0.5" rpy="0 0 0"/>
        <mass value="0.030"/>
        <inertia ixx="0.001" ixy="0.0"  ixz="0.0"  iyy="0.001"  iyz="0.0"  izz="0.001"/>
    </inertial>
</link>>

<joint name="fixed_joint" type="fixed">
    <parent link="world"/>
    <child link="link1"/>
    <origin xyz="0 0 0" rpy="0 0 0"/>
</joint>



 <joint name="joint1" type="continuous">
  <parent link="link1"/>
  <child link="link2"/>
  <origin xyz="0 0.1 0.9" rpy="0 0 0"/>
  <axis xyz=" 0 1 0"/>
 </joint>

<gazebo>
    <plugin name="gazebo_ros_control" filename="libgazebo_ros_control.so">
        <robotNamespace>/arm</robotNamespace>
        <robotSimType>gazebo_ros_control/DefaultRobotHWSim</robotSimType>
    </plugin>
</gazebo>

<transmission name="tran1">
    <type>transmission_interface/SimpleTransmission</type>
    <joint name="joint1"> <hardwareInterface>EffortJointInterface</hardwareInterface>     </joint>
    <actuator name="motor1">
        <hardwareInterface>EffortJointInterface</hardwareInterface>
        <mechanicalReduction>1</mechanicalReduction>
    </actuator>
</transmission>

 
</robot>
